Workbook

Sheet Page de garde

Sheet DPGF - LOT 2 Champs Philippe
B3: HAUT DE SEINE HABITAT RPA CHAMPS PHILIPPE
F5: Lot 2 : Réseaux
B7: N° | C7: DESIGNATION | G7: U | H7: Q | I7: PU | J7: Montants
I8: (euros) | J8: (euros)
C9: DÉCHETS le cas échéant
D10: - | E10: Travaux de retrait, manipulation et évacuation de matériaux amiantés, selon descriptif CCTP | G10: Ens | H10: 1 | J10: =H10*I10 -> 0
D11: - | E11: Travaux de retrait, manipulation et évacuation de matériaux plombés, selon descriptif CCTP | G11: Ens | H11: 1 | J11: =H11*I11 -> 0
C13: TOTAL DECHETS….......... | J13: =SUM(J9:J12) -> 0
B15: 2 | C15: LOT 2 - ETUDE D'EXECUTION, INSTALLATION DE CHANTIER ET TRAVAUX PREPARATOIRES
D16: - | E16: Etude d'exécution (Synoptique hydraulique, dimensionnement tuyauterie, calcul de dilatation, étude de structure) | G16: Ens | H16: 1 | J16: =H16*I16 -> 0
D17: - | E17: Installation de chantier | G17: Ens | H17: 1 | J17: =H17*I17 -> 0
D18: - | E18: Repérages avant intervention en logement | G18: Ens | H18: 1 | J18: =H18*I18 -> 0
D19: - | E19: Etat des lieux - Reportage photos | G19: Ens | H19: 1 | J19: =H19*I19 -> 0
D20: - | E20: Protection des ouvrages - Logements | G20: Ens | H20: 1 | J20: =H20*I20 -> 0
C23: TOTAL PARTIE 2….......... | J23: =SUM(J13:J21) -> 0
B25: 3 | C25: LOT 2 - TRAVAUX DISTRIBUTION
B27: 3.1 | C27: Dépose
D28: - | E28: Neutralisation, vidange, dépose de l’ensemble des réseaux horizontaux, y compris calorifuge, vannerie et supports | G28: Ens | H28: 1 | J28: =H28*I28 -> 0
D29: - | E29: Déconnexion des logements et dépose des réseaux verticaux, y compris supports | G29: Ens | H29: 1 | J29: =H29*I29 -> 0
C31: TOTAL PARTIE 3.1….......... | J31: =+SUM(J28:J29) -> 0
B33: 3.2 | C33: Distribution horizontale ECS
D34: - | E34: Percements dans les parois, murs porteurs, poutres, … (parking) | G34: Ens | H34: 1 | J34: =H34*I34 -> 0
D35: - | E35: Tube multicouches conforme au CCTP | G35: ml | H35: 320 | J35: =H35*I35 -> 0
D37: Pieds de colonnes ECS:
D38: - | E38: Vanne d'isolement | G38: U | H38: 15 | J38: =H37*I37 -> 0
D39: - | E39: Vanne de vidange DN 15 bouchonnée | G39: U | H39: 15 | J39: =H38*I38 -> 0
D41: Pieds de colonnes RECS
D42: - | E42: Vanne d'isolement | G42: U | H42: 15 | J42: =H41*I41 -> 0
D43: - | E43: Vanne autoréglage CALEFFI | G43: U | H43: 15 | J43: =H42*I42 -> 0
D44: - | E44: Vanne de vidange DN 15 bouchonnée | G44: U | H44: 15 | J44: =H43*I43 -> 0
D46: Prescriptions Complémentaires:
D47: - | E47: Calorifuge 30 mm finition PVC | G47: m2 | H47: 200 | J47: =H46*I46 -> 0
D48: - | E48: Dépose et mise en place de faux plafond visitable sous-sol (bâtiment A et B) | G48: Ens | H48: 1 | J48: =H47*I47 -> 0
C50: TOTAL PARTIE 3.2….......... | J50: =+SUM(J34:J48) -> 0
B52: 3.3 | C52: Distribution verticale ECS
D53: - | E53: Tube multicouches conforme au CCTP | G53: ml | H53: 450 | J53: =H52*I52 -> 0
D55: Tête de colonnes ECS
D56: - | E56: Vanne d'isolement | G56: U | H56: 15 | J56: =H55*I55 -> 0
D57: - | E57: Purgeur grand débit | G57: U | H57: 15 | J57: =H56*I56 -> 0
D59: Prescriptions Complémentaires:
...

Sheet Récap - LOT 2
A1: Hauts-de-Seine Habitat
A2: 15-17 avenue de Verdun à la Garenne-Colombes, 92250
A3: ='DPGF - LOT 2 Champs Philippe'!F5 -> Lot 2 : Réseaux
A4: =+[1]DPGF!A6 -> N° | B4: =+[1]DPGF!B6 -> DÉSIGNATION | C4: =+[1]DPGF!I6 -> Prix Total
A5: =+[1]DPGF!#REF! -> #REF! | B5: =+[1]DPGF!#REF! -> #REF! | C5: =+[1]DPGF!I7 -> (€ HT)
A7: =+'DPGF - LOT 2 Champs Philippe'!B15 -> 2 | B7: =+'DPGF - LOT 2 Champs Philippe'!C15 -> LOT 2 - ETUDE D'EXECUTION, INSTALLATION DE CHANTIER ET TRAVAUX PREPARATOIRES | C7: =+'DPGF - LOT 2 Champs Philippe'!J23 -> 0
A9: =+'DPGF - LOT 2 Champs Philippe'!B25 -> 3 | B9: =+'DPGF - LOT 2 Champs Philippe'!C25 -> LOT 2 - TRAVAUX DISTRIBUTION | C9: =+'DPGF - LOT 2 Champs Philippe'!J84 -> 0
A10: =+'DPGF - LOT 2 Champs Philippe'!B27 -> 3.1 | B10: =+'DPGF - LOT 2 Champs Philippe'!C27 -> Dépose | C10: =+'DPGF - LOT 2 Champs Philippe'!J31 -> 0
A11: =+'DPGF - LOT 2 Champs Philippe'!B33 -> 3.2 | B11: =+'DPGF - LOT 2 Champs Philippe'!C33 -> Distribution horizontale ECS | C11: =+'DPGF - LOT 2 Champs Philippe'!J50 -> 0
A12: =+'DPGF - LOT 2 Champs Philippe'!B52 -> 3.3 | B12: =+'DPGF - LOT 2 Champs Philippe'!C52 -> Distribution verticale ECS | C12: =+'DPGF - LOT 2 Champs Philippe'!J62 -> 0
A13: =+'DPGF - LOT 2 Champs Philippe'!B64 -> 3.4 | B13: =+'DPGF - LOT 2 Champs Philippe'!C64 -> Travaux en logement | C13: =+'DPGF - LOT 2 Champs Philippe'!J74 -> 0
A14: =+'DPGF - LOT 2 Champs Philippe'!B76 -> 3.5 | B14: =+'DPGF - LOT 2 Champs Philippe'!C76 -> Equilibrage | C14: =+'DPGF - LOT 2 Champs Philippe'!J82 -> 0
A16: ='DPGF - LOT 2 Champs Philippe'!B86 -> 4 | B16: =+'DPGF - LOT 2 Champs Philippe'!C86 -> LOT 2 - TRAVAUX FIN DE CHANTIER | C16: ='DPGF - LOT 2 Champs Philippe'!J94 -> 0
B18: Total LOT 2 - Travaux distribution €HT | C18: =+'DPGF - LOT 2 Champs Philippe'!J97 -> 0
B19: TVA (10%) | C19: =+'DPGF - LOT 2 Champs Philippe'!J98 -> 0
B20: Total LOT 2 - Travaux distribution €TTC | C20: =+'DPGF - LOT 2 Champs Philippe'!J99 -> 0
B22: Date
B24: Signature et cachet
