Workbook

Sheet Page de garde

Sheet DPGF - LOT 1 Champs Philippe
B3: HAUT DE SEINE HABITAT RPA CHAMPS PHILIPPE
F5: Lot 1 : production
B7: N° | C7: DESIGNATION | G7: U | H7: Q | I7: PU | J7: Montants
I8: (euros) | J8: (euros)
C9: DÉCHETS le cas échéant
D10: - | E10: Travaux de retrait, manipulation et évacuation de matériaux amiantés y compris entoilage des parois intérieures, selon descriptif CCTP | G10: Ens | H10: 1 | J10: =H10*I10 -> 0
D11: - | E11: Travaux de retrait, manipulation et évacuation de matériaux plombés, selon descriptif CCTP | G11: Ens | H11: 1 | J11: =H11*I11 -> 0
C13: TOTAL DECHETS….......... | J13: =SUM(J9:J12) -> 0
B15: 2 | C15: LOT 1 - ETUDE D'EXECUTION, INSTALLATION DE CHANTIER ET TRAVAUX PREPARATOIRES
D16: - | E16: Etude d'exécution (Synoptique hydraulique, dimensionnement tuyauterie, calcul de dilatation, étude de structure) | G16: Ens | H16: 1 | J16: =H16*I16 -> 0
D17: - | E17: Installation de chantier | G17: Ens | H17: 1 | J17: =H17*I17 -> 0
D18: - | E18: Etat des lieux - Reportage photos | G18: Ens | H18: 1 | J18: =H18*I18 -> 0
D19: - | E19: Dépose et évacuation des équipements (production) | G19: Ens | H19: 1 | J19: =H19*I19 -> 0
C22: TOTAL PARTIE 2….......... | J22: =SUM(J13:J21) -> 0
B24: 3 | C24: LOT 1 - TRAVAUX PRODUCTION
B26: 3.2 | C26: Mise en place de la production provisoire
D27: - | E27: Mise en place de la production provisoire | G27: Ens | H27: 1 | J27: =H27*I27 -> 0
C29: TOTAL PARTIE 3.2….......... | J29: =SUM(J27) -> 0
B31: 3.3 | C31: Mise en place de la PAC et du ballon
B32: 3.3.1 | D32: Fourniture et mise en place PAC , ballons de stockage et réchauffeur de boucle
D33: - | E33: Fourniture et mise en place de la PAC | G33: Ens | H33: 1 | J33: =H33*I33 -> 0
D34: - | E34: Fourniture et mise en place du ballons de stockage | G34: Ens | H34: 1 | J34: =H34*I34 -> 0
D35: - | E35: Fourniture et mise en place du réchauffeur de boucle | G35: U | H35: 1 | J35: =H35*I35 -> 0
D36: - | E36: Boitier de commande | G36: U | H36: 1 | J36: =H36*I36 -> 0
D37: - | E37: Vannes d’isolement au niveau des piquages | G37: U | H37: 5 | J37: =H37*I37 -> 0
D38: - | E38: Vanne de vidange avec raccordement au puisard | G38: U | H38: 2 | J38: =H38*I38 -> 0
D39: - | E39: Purgeur automatique en point haut avec vanne d’isolement, | G39: U | H39: 3 | J39: =H39*I39 -> 0
D40: - | E40: Thermomètres | G40: U | H40: 5 | J40: =H40*I40 -> 0
D41: - | E41: Vase d'expansion | G41: U | H41: 1 | J41: =H41*I41 -> 0
D42: - | E42: V3V+ servomoteur | G42: U | H42: 1 | J42: =H42*I42 -> 0
D43: - | E43: Un groupe de sécurité ou un ensemble vanne, clapet et soupape de sécurité sur l’alimentation EF | G43: U | H43: 1 | J43: =H43*I43 -> 0
D44: - | E44: Filtre, un réducteur de pression | G44: U | H44: 1 | J44: =H44*I44 -> 0
... D48: - | E48: Implantation Unité extérieure PAC ( Dalle + Enclos ) | G48: U | H48: 1 | J48: =H48*I48 -> 0
C50: TOTAL sous-partie 3.3.1………………………….. | J50: =+SUM(J33:J48) -> 0
B52: 3.3.2 | D52: Raccordement électrique, mise au norme de l’amoire électrique | G52: Ens | H52: 1 | J52: =H52*I52 -> 0
D53: - | E53: Alimentation Hydragreen triphasée | G53: pm
D54: - | E54: Raccordement afficheur sur PAC Maître | G54: pm
D55: - | E55: Alimentation électrique de la vanne 3 voies hors gel par l’unité extérieure en 200 V | G55: pm
D56: - | E56: Alimentation électrique vanne 3 voies hors gel | G56: pm
D57: - | E57: Raccordement des sondes à la PAC Maître | G57: pm
...

Sheet Récap- LOT 1
A1: Hauts-de-Seine Habitat
A2: 15-17 avenue de Verdun à la Garenne-Colombes, 92250
A3: ='DPGF - LOT 1 Champs Philippe'!F5 -> Lot 1 : production
A4: =+[1]DPGF!A6 -> N° | B4: =+[1]DPGF!B6 -> DÉSIGNATION | C4: =+[1]DPGF!I6 -> Prix Total
A5: =+[1]DPGF!#REF! -> #REF! | B5: =+[1]DPGF!#REF! -> #REF! | C5: =+[1]DPGF!I7 -> (€ HT)
A7: =+'DPGF - LOT 1 Champs Philippe'!B15 -> 2 | B7: =+'DPGF - LOT 1 Champs Philippe'!C15 -> LOT 1 - ETUDE D'EXECUTION, INSTALLATION DE CHANTIER ET TRAVAUX PREPARATOIRES | C7: ='DPGF - LOT 1 Champs Philippe'!J22 -> 0
A9: =+'DPGF - LOT 1 Champs Philippe'!B24 -> 3 | B9: =+'DPGF - LOT 1 Champs Philippe'!C24 -> LOT 1 - TRAVAUX PRODUCTION | C9: ='DPGF - LOT 1 Champs Philippe'!J166 -> 0
A10: =+'DPGF - LOT 1 Champs Philippe'!B26 -> 3.2 | B10: =+'DPGF - LOT 1 Champs Philippe'!C26 -> Mise en place de la production provisoire | C10: ='DPGF - LOT 1 Champs Philippe'!J29 -> 0
A11: =+'DPGF - LOT 1 Champs Philippe'!B31 -> 3.3 | B11: =+'DPGF - LOT 1 Champs Philippe'!C31 -> Mise en place de la PAC et du ballon | C11: ='DPGF - LOT 1 Champs Philippe'!J99 -> 0
A12: =+'DPGF - LOT 1 Champs Philippe'!B101 -> 3.4 | B12: =+'DPGF - LOT 1 Champs Philippe'!C101 -> Circuits ECS et EF dans la sous-station | C12: ='DPGF - LOT 1 Champs Philippe'!J137 -> 0
A13: =+'DPGF - LOT 1 Champs Philippe'!B139 -> 3.5 | B13: =+'DPGF - LOT 1 Champs Philippe'!C139 -> Calorifuge | C13: ='DPGF - LOT 1 Champs Philippe'!J142 -> 0
A14: =+'DPGF - LOT 1 Champs Philippe'!B144 -> 3.6 | B14: =+'DPGF - LOT 1 Champs Philippe'!C144 -> Flocage du local technique | C14: ='DPGF - LOT 1 Champs Philippe'!J147 -> 0
A15: =+'DPGF - LOT 1 Champs Philippe'!B149 -> 3.7 | B15: =+'DPGF - LOT 1 Champs Philippe'!C149 -> Installation d’éclairage supplémentaire | C15: ='DPGF - LOT 1 Champs Philippe'!J152 -> 0
A16: =+'DPGF - LOT 1 Champs Philippe'!B154 -> 3.8 | B16: =+'DPGF - LOT 1 Champs Philippe'!C154 -> Ragréage du sol et peinture | C16: ='DPGF - LOT 1 Champs Philippe'!J159 -> 0
A17: =+'DPGF - LOT 1 Champs Philippe'!B161 -> 3.9 | B17: =+'DPGF - LOT 1 Champs Philippe'!C161 -> Enclos acoustique | C17: ='DPGF - LOT 1 Champs Philippe'!J164 -> 0
A19: ='DPGF - LOT 1 Champs Philippe'!B168 -> 4 | B19: =+'DPGF - LOT 1 Champs Philippe'!C168 -> LOT 1 - TRAVAUX FIN DE CHANTIER | C19: =+'DPGF - LOT 1 Champs Philippe'!J176 -> 0
B23: Total LOT 1 - Travaux production €HT | C23: ='DPGF - LOT 1 Champs Philippe'!J179 -> 0
B24: TVA (10%) | C24: ='DPGF - LOT 1 Champs Philippe'!J180 -> 0
B25: Total LOT 1 - Travaux production €TTC | C25: ='DPGF - LOT 1 Champs Philippe'!J181 -> 0
B27: Date
B29: Signature et cachet
